Workbook
Name ASO: 引用数据!$H$2:$H$13
Name miRNA类: 引用数据!$E$2:$E$13
Name miRNA文库: 引用数据!$F$2:$F$13
Name RNAi服务: 引用数据!$D$2:$D$13
Name RNAi文库: 引用数据!$C$2:$C$13
Name siRNA类: 引用数据!$A$2:$A$13
Name 常规RNA合成: 引用数据!$B$2:$B$13
Name 基因编辑: 引用数据!$G$2:$G$13

Sheet RNA单靶点定制表
B1: 百力格生物科技（上海）股份有限公司 RNA服务与套餐订购表
A4: 订购日期： | G4: 地址：上海市松江区书海路99号23幢
A5: 客户姓名：* | G5: 联系电话：021-57632761, 400-168-8906
A6: 客户单位：* | G6: 网址：www.bioligo.com
A7: 课题组：* | G7: 邮箱：blg-rna@bioligo.com
A8: 订单类别： | B8: RNA | G8: 订单要求：
A9: 客户地址：* | G9: 1.此表格仅针对E-mail订单使用，如果工作日19点前2小时未收到回复请及时联系。 2.因为订单是系统自动处理，订单发送前请仔细核对信息, 订单接收2小时后将不能再更改。 3.修饰请用下拉菜单中我们公司的专用代码，如果没有的修饰种类请在备注栏中备注或电话联系我们。
A10: 客户电话：*
A11: 客户Email：
A12: 交付形式：
A13: 客户ID:
A14: 客户订单号：
A15: 收货人：* | C15: 收货电话：*
A16: 收货地址：*
A17: 发票类型：* | G17: 兼并碱基代码：A,g＝R；A,C＝M；A,T＝W；C,g=S；C,T＝Y；g,T＝K；A,T,C＝H；g,T,C＝B；g,A,T=D；A,C,g=V；A,C,g,T=N
A18: 发票抬头：*
A19: ID* | B19: 引物名称 | C19: 引物序列(5'to3') | D19: 反向互补序列(5'to3') | E19: 纯化方式 | F19: 5'修饰 | G19: 3'修饰 | H19: 反向互补5'修饰 | I19: 反向互补3'修饰 | J19: 分装管数 | K19: 每管OD值 | L19: 每管nmoles | M19: 标签类型 | N19: 离心管类型 | O19: 溶解浓度(uM) | P19: 检验报告类型 | Q19: 备注 | R19: 碱基数
R20: {=LEN(C20)-SUM((LEN(C20)-LEN(SUBSTITUTE(C20,修饰列表!$B$2:$B$79,修饰列表!$D$2:$D$79))))} -> 0
R21: {=LEN(C21)-SUM((LEN(C21)-LEN(SUBSTITUTE(C21,修饰列表!$B$2:$B$79,修饰列表!$D$2:$D$79))))} -> 0
R22: {=LEN(C22)-SUM((LEN(C22)-LEN(SUBSTITUTE(C22,修饰列表!$B$2:$B$79,修饰列表!$D$2:$D$79))))} -> 0
R23: {=LEN(C23)-SUM((LEN(C23)-LEN(SUBSTITUTE(C23,修饰列表!$B$2:$B$79,修饰列表!$D$2:$D$79))))} -> 0
R24: {=LEN(C24)-SUM((LEN(C24)-LEN(SUBSTITUTE(C24,修饰列表!$B$2:$B$79,修饰列表!$D$2:$D$79))))} -> 0
R25: {=LEN(C25)-SUM((LEN(C25)-LEN(SUBSTITUTE(C25,修饰列表!$B$2:$B$79,修饰列表!$D$2:$D$79))))} -> 0
R26: {=LEN(C26)-SUM((LEN(C26)-LEN(SUBSTITUTE(C26,修饰列表!$B$2:$B$79,修饰列表!$D$2:$D$79))))} -> 0
R27: {=LEN(C27)-SUM((LEN(C27)-LEN(SUBSTITUTE(C27,修饰列表!$B$2:$B$79,修饰列表!$D$2:$D$79))))} -> 0
R28: {=LEN(C28)-SUM((LEN(C28)-LEN(SUBSTITUTE(C28,修饰列表!$B$2:$B$79,修饰列表!$D$2:$D$79))))} -> 0
R29: {=LEN(C29)-SUM((LEN(C29)-LEN(SUBSTITUTE(C29,修饰列表!$B$2:$B$79,修饰列表!$D$2:$D$79))))} -> 0
R30: {=LEN(C30)-SUM((LEN(C30)-LEN(SUBSTITUTE(C30,修饰列表!$B$2:$B$79,修饰列表!$D$2:$D$79))))} -> 0
R31: {=LEN(C31)-SUM((LEN(C31)-LEN(SUBSTITUTE(C31,修饰列表!$B$2:$B$79,修饰列表!$D$2:$D$79))))} -> 0
... R60: {=LEN(C60)-SUM((LEN(C60)-LEN(SUBSTITUTE(C60,修饰列表!$B$2:$B$79,修饰列表!$D$2:$D$79))))} -> 0
R61: =LEN(C61)-SUM((LEN(C61)-LEN(SUBSTITUTE(C61,修饰列表!$B$2:$B$80,修饰列表!$D$2:$D$80)))) -> 0
R62: =LEN(C62)-SUM((LEN(C62)-LEN(SUBSTITUTE(C62,修饰列表!$B$2:$B$80,修饰列表!$D$2:$D$80)))) -> 0
R63: =LEN(C63)-SUM((LEN(C63)-LEN(SUBSTITUTE(C63,修饰列表!$B$2:$B$80,修饰列表!$D$2:$D$80)))) -> 0
R64: =LEN(C64)-SUM((LEN(C64)-LEN(SUBSTITUTE(C64,修饰列表!$B$2:$B$80,修饰列表!$D$2:$D$80)))) -> 0
R65: =LEN(C65)-SUM((LEN(C65)-LEN(SUBSTITUTE(C65,修饰列表!$B$2:$B$80,修饰列表!$D$2:$D$80)))) -> 0
R66: =LEN(C66)-SUM((LEN(C66)-LEN(SUBSTITUTE(C66,修饰列表!$B$2:$B$80,修饰列表!$D$2:$D$80)))) -> 0
R67: =LEN(C67)-SUM((LEN(C67)-LEN(SUBSTITUTE(C67,修饰列表!$B$2:$B$80,修饰列表!$D$2:$D$80)))) -> 0
R68: =LEN(C68)-SUM((LEN(C68)-LEN(SUBSTITUTE(C68,修饰列表!$B$2:$B$80,修饰列表!$D$2:$D$80)))) -> 0
R69: =LEN(C69)-SUM((LEN(C69)-LEN(SUBSTITUTE(C69,修饰列表!$B$2:$B$80,修饰列表!$D$2:$D$80)))) -> 0
R70: =LEN(C70)-SUM((LEN(C70)-LEN(SUBSTITUTE(C70,修饰列表!$B$2:$B$80,修饰列表!$D$2:$D$80)))) -> 0
...

Sheet 套装订购
B1: 百力格生物科技（上海）股份有限公司
A4: 订购日期： | G4: 地址：上海市松江区书海路99号23幢
A5: 客户姓名：* | G5: 联系电话：021-67616018, 400-168-8906
A6: 客户单位：* | G6: 网址：www.bioligo.com
A7: 课题组：* | G7: 邮箱：blg-rna@bioligo.com
A8: 订单类别： | G8: 订单要求：
A9: 客户地址：* | G9: 1.此表格仅针对E-mail订单使用，如果工作日19点前2小时未收到回复请及时联系。 2.因为订单是系统自动处理，订单发送前请仔细核对信息, 订单接收2小时后将不能再更改。 3.修饰请用下拉菜单中我们公司的专用代码，如果没有的修饰种类请在备注栏中备注或电话联系我们。
A10: 客户电话：*
A11: 客户Email：
A12: 交付形式：
A13: 客户ID:
A14: 客户订单号：
A15: 收货人：* | C15: 收货电话：*
A16: 收货地址：*
A17: 发票类型：* | G17: 兼并碱基代码：A,g＝R；A,C＝M；A,T＝W；C,g=S；C,T＝Y；g,T＝K；A,T,C＝H；g,T,C＝B；g,A,T=D；A,C,g=V；A,C,g,T=N
A18: 发票抬头：*
A19: 序号 | B19: 基因名称 | C19: 基因ID | D19: 物种 | E19: 产品类型 | G19: 产品名称 | J19: 产品编号 | K19: 规格 | L19: 数量 | M19: 特殊说明
A20: 1 | K20: =VLOOKUP(J20,套装说明!C:D,2,0) -> #N/A
A21: 2 | K21: =VLOOKUP(J21,套装说明!C:D,2,0) -> #N/A
A22: 3 | K22: =VLOOKUP(J22,套装说明!C:D,2,0) -> #N/A
A23: 4 | K23: =VLOOKUP(J23,套装说明!C:D,2,0) -> #N/A
A24: 5 | K24: =VLOOKUP(J24,套装说明!C:D,2,0) -> #N/A
A25: 6 | K25: =VLOOKUP(J25,套装说明!C:D,2,0) -> #N/A
A26: 7 | K26: =VLOOKUP(J26,套装说明!C:D,2,0) -> #N/A
A27: 8 | K27: =VLOOKUP(J27,套装说明!C:D,2,0) -> #N/A
A28: 9 | K28: =VLOOKUP(J28,套装说明!C:D,2,0) -> #N/A
A29: 10 | K29: =VLOOKUP(J29,套装说明!C:D,2,0) -> #N/A
A30: 11 | K30: =VLOOKUP(J30,套装说明!C:D,2,0) -> #N/A
A31: 12 | K31: =VLOOKUP(J31,套装说明!C:D,2,0) -> #N/A
... A39: 20 | K39: =VLOOKUP(J39,套装说明!C:D,2,0) -> #N/A

Sheet 套装说明
A1: 产品类别 | B1: 产品名称 | C1: 产品编号 | D1: 规格 | E1: 价格 | F1: 赠送
A2: siRNA类 | B2: siRNA常规单靶点合成 | C2: PRsi001-002 | D2: 2.5nmol | E2: 398 | F2: 阴性对照2.5nmol
C3: PRsi001-005 | D3: 5nmol | E3: 498 | F3: 阴性对照2.5nmol
C4: PRsi001-010 | D4: 10nmol | E4: 698 | F4: 阴性对照2.5nmol
C5: PRsi001-100 | D5: 100nmol | E5: 3988 | F5: 阴性对照2.5nmol
C6: PRsi001-200 | D6: 200nmol | E6: 询价 | F6: 阴性对照2.5nmol
C7: PRsi001-500 | D7: 500nmol | E7: 询价 | F7: 阴性对照2.5nmol
C8: PRsi001-201 | D8: 1umol | E8: 询价 | F8: 阴性对照2.5nmol
C9: PRsi001-101 | D9: 100mg | E9: 询价 | F9: 阴性对照2.5nmol
C10: PRsi001-102 | D10: 200mg | E10: 询价 | F10: 阴性对照2.5nmol
C11: PRsi001-105 | D11: 500mg | E11: 询价 | F11: 阴性对照2.5nmol
C12: PRsi001-110 | D12: 1g | E12: 询价 | F12: 阴性对照2.5nmol
B13: UHP- siRNA化学修饰单靶点合成 Ultra-High Performance UHP | C13: PRsiu002-002 | D13: 2.5nmol | E13: 958 | F13: 阴性对照2.5nmol
C14: PRsiu002-005 | D14: 5nmol | E14: 1258 | F14: 阴性对照2.5nmol
C15: PRsiu002-010 | D15: 10nmol | E15: 1958 | F15: 阴性对照2.5nmol
C16: PRsiu002-100 | D16: 100nmol | E16: 9958 | F16: 阴性对照2.5nmol
C17: PRsiu002-200 | D17: 200nmol | E17: 询价 | F17: 阴性对照2.5nmol
C18: PRsiu002-500 | D18: 500nmol | E18: 询价 | F18: 阴性对照2.5nmol
C19: PRsiu002-201 | D19: 1umol | E19: 询价 | F19: 阴性对照2.5nmol
C20: PRsiu002-101 | D20: 100mg | E20: 询价 | F20: 阴性对照2.5nmol
C21: PRsiu002-102 | D21: 200mg | E21: 询价 | F21: 阴性对照2.5nmol
C22: PRsiu002-105 | D22: 500mg | E22: 询价 | F22: 阴性对照2.5nmol
C23: PRsiu002-110 | D23: 1g | E23: 询价 | F23: 阴性对照2.5nmol
B24: siRNA常规1/3套餐合成 | C24: PRsit003-003 | D24: 5nmol*3 | E24: 1868 | F24: 阴性对照2.5nmol，荧光标记阴性对照2.5nmol，阳性对照2.5nmol
B25: siRNA常规2/5套餐合成 | C25: PRsit003-005 | D25: 5nmol*5 | E25: 2668 | F25: 阴性对照2.5nmol，荧光标记阴性对照2.5nmol，阳性对照2.5nmol
B26: siRNA常规1/3即用型套餐合成 | C26: PRsit004-003 | D26: 5nmol*3 | E26: 2568 | F26: 转染试剂500ul，阴性对照2.5nmol，荧光标记阴性对照2.5nmol，阳性对照2.5nmol
B27: siRNA常规2/5即用型套餐合成 | C27: PRsit004-005 | D27: 5nmol*5 | E27: 3368 | F27: 转染试剂500ul，阴性对照2.5nmol，荧光标记阴性对照2.5nmol，阳性对照2.5nmol
B28: UHP-siRNA化学修饰1/3套餐合成 | C28: Prsiut005-003 | D28: 5nmol*3 | E28: 3996 | F28: 阴性对照2.5nmol，荧光标记阴性对照2.5nmol，阳性对照2.5nmol
B29: UHP-siRNA化学修饰2/5套餐合成 | C29: Prsiut005-005 | D29: 5nmol*5 | E29: 5996 | F29: 阴性对照2nmol，荧光标记阴性对照1nmol，阳性对照1nmol
B30: UHP-siRNA即用型化学修饰1/3套餐合成 | C30: Prsiut006-003 | D30: 5nmol*3 | E30: 4796 | F30: 转染试剂500ul，阴性对照2.5nmol，荧光标记阴性对照2.5nmol，阳性对照2.5nmol
B31: UHP-siRNA即用型化学修饰2/5套餐合成 | C31: Prsiut006-005 | D31: 5nmol*5 | E31: 6796 | F31: 转染试剂500ul，阴性对照2nmol，荧光标记阴性对照1nmol，阳性对照1nmol
A32: 常规RNA合成 | B32: RNA常规定制合成（16~30nt） | C32: PR001-005 | D32: 5nmol | E32: 398
B33: RNA非修饰超短定制合成（ 10~15nt） | C33: PR002-005 | D33: 5nmol | E33: 698
B34: RNA非修饰长序列定制合成（31~59nt） | C34: PR003-005 | D34: 5nmol | E34: 1518
B35: RNA非修饰超长序列定制合成（60~120nt） | C35: PR004-005 | D35: 5nmol | E35: 2518
B36: RNA修饰定制合成（16~30nt） | C36: PR005-005 | D36: 5nmol | E36: 498
B37: RNA修饰超短定制合成（ 10~15nt） | C37: PR006-005 | D37: 5nmol | E37: 798
B38: RNA修饰长序列定制合成（31~59nt） | C38: PR007-005 | D38: 5nmol | E38: 1618
B39: RNA修饰超长序列定制合成（60~120nt） | C39: PR008-005 | D39: 5nmol | E39: 2618
A40: RNAi文库 | B40: 定制化siRNA 文库 | C40: PR010 | D40: 0.25nmol | E40: 询价
...

Sheet 引用数据
A1: siRNA类 | B1: 常规RNA合成 | C1: RNAi文库 | D1: RNAi服务 | E1: miRNA类 | F1: miRNA文库 | G1: 基因编辑 | H1: ASO
A2: siRNA常规单靶点合成 | B2: RNA常规定制合成（16~30nt） | C2: 定制化siRNA 文库 | D2: 有效靶点筛选验证服务 | E2: 常规miRNA mimics合成 | F2: homo miRNA 文库 A库（5p） | G2: 常规crRNA合成 | H2: UHP ASO
A3: UHP-siRNA化学修饰单靶点合成 Ultra-High Performance UHP | B3: RNA非修饰超短定制合成（ 10~15nt） | C3: Human Genome siRNA Premix Library | D3: 细胞功能验证服务 | E3: 常规miRNA Inhibitor合成 | F3: homo miRNA 文库 B库（3p） | G3: 常规tracraRNA合成 | H3: FUHP SiASO
A4: siRNA常规1/3套餐合成 | B4: RNA非修饰长序列定制合成（31~59nt） | C4: RBP siRNA文库 | E4: 修饰miRNA agomir合成 | F4: Mus miRNA 文库 A库（5p） | G4: 常规gRNA合成 | H4: ASO常规定制
A5: siRNA常规2/5套餐合成 | B5: RNA非修饰超长序列定制合成（60~120nt） | C5: Kinase | E5: 修饰miRNA antagomir合成 | F5: Mus miRNA 文库 B库（3p） | G5: 修饰crRNA合成 | H5: ASO特殊修饰客户定制
A6: siRNA常规1/3即用型套餐合成 | B6: RNA修饰定制合成（16~30nt） | C6: Phosphtases | E6: pre-miRNA mimic | F6: Rat miRNA 文库 A库（5p） | G6: 化学修饰tracraRNA合成 | H6: 有效靶点筛选验证服务
A7: siRNA常规2/5即用型套餐合成 | B7: RNA修饰超短定制合成（ 10~15nt） | C7: Chemokine Receptors | F7: Rat miRNA 文库 B库（3p） | G7: 修饰gRNA合成 | H7: 细胞功能验证服务
A8: UHP-siRNA化学修饰1/3套餐合成 | B8: RNA修饰长序列定制合成（31~59nt） | C8: Proteases gene | F8: 双荧光素有效靶点筛选验证服务
A9: UHP-siRNA化学修饰2/5套餐合成 | B9: RNA修饰超长序列定制合成（60~120nt） | C9: Metastasis gene | F9: 细胞功能验证服务
A10: UHP-siRNA即用型化学修饰1/3套餐合成 | C10: Apoptosis
A11: UHP-siRNA即用型化学修饰2/5套餐合成 | C11: Transcription factors
C12: Human Epigenetics siRNA Library
C13: Silencer™ Select 人药物靶标 siRNA 文库（384 孔）

Sheet 修饰列表
B1: DNA修饰 | I1: RNA修饰
A2: 中间修饰 | B2: 代码 | C2: 修饰碱基 | D2: 碱基数 | E2: 常用兼并碱基代码 | H2: 中间修饰 | I2: 代码 | J2: 碱基数 | K2: 常用兼并碱基代码
A3: 2`-O-Methyl A | B3: /i2OMeA/ | C3: A | D3: =LEN(C3) -> 1 | E3: M:(A/C) | F3: V:(A/C/G) | H3: dA | I3: dA | J3: 1 | K3: M:(A/C) | L3: V:(A/C/G)
A4: 2`-O-Methyl B | B4: /i2OMeB/ | C4: B | D4: =LEN(C4) -> 1 | E4: R:(A/G) | F4: H:(A/C/T) | H4: dG | I4: dG | J4: 1 | K4: R:(A/G) | L4: H:(A/C/U)
A5: 2`-O-Methyl C | B5: /i2OMeC/ | C5: C | D5: =LEN(C5) -> 1 | E5: W:(A/T) | F5: D:(A/G/T) | H5: dC | I5: dC | J5: 1 | K5: W:(A/U) | L5: D:(A/G/U)
A6: 2`-O-Methyl D | B6: /i2OMeD/ | C6: D | D6: =LEN(C6) -> 1 | E6: S:(C/G) | F6: B:(C/G/T) | H6: dT | I6: dT | J6: 1 | K6: S:(C/G) | L6: B:(C/G/U)
A7: 2`-O-Methyl G | B7: /i2OMeG/ | C7: G | D7: =LEN(C7) -> 1 | E7: Y:(C/T) | F7: N:(A/G/C/T) | H7: LNA-A | I7: +A | J7: 1 | K7: Y:(C/U) | L7: N:(A/G/C/U)
A8: 2`-O-Methyl H | B8: /i2OMeH/ | C8: H | D8: =LEN(C8) -> 1 | E8: K:(G/T) | H8: LNA-C | I8: +C | J8: 1 | K8: K:(G/U)
A9: 2`-O-Methyl K | B9: /i2OMeK/ | C9: K | D9: =LEN(C9) -> 1 | H9: LNA-G | I9: +G | J9: 1
A10: 2`-O-Methyl M | B10: /i2OMeM/ | C10: M | D10: =LEN(C10) -> 1 | H10: LNA-U | I10: +T | J10: 1
A11: 2`-O-Methyl N | B11: /i2OMeN/ | C11: N | D11: =LEN(C11) -> 1
A12: 2`-O-Methyl R | B12: /i2OMeR/ | C12: R | D12: =LEN(C12) -> 1
A13: 2`-O-Methyl S | B13: /i2OMeS/ | C13: S | D13: =LEN(C13) -> 1
A14: 2`-O-Methyl U | B14: /i2OMeU/ | C14: U | D14: =LEN(C14) -> 1
A15: 2`-O-Methyl V | B15: /i2OMeV/ | C15: V | D15: =LEN(C15) -> 1
A16: 2`-O-Methyl W | B16: /i2OMeW/ | C16: W | D16: =LEN(C16) -> 1
A17: 2`-O-Methyl Y | B17: /i2OMeY/ | C17: Y | D17: =LEN(C17) -> 1
A18: 2F-RNA A | B18: /i2FA/ | C18: A | D18: =LEN(C18) -> 1
A19: 2F-RNA C | B19: /i2FC/ | C19: C | D19: =LEN(C19) -> 1
A20: 2F-RNA G | B20: /i2FG/ | C20: G | D20: =LEN(C20) -> 1
A21: 2F-RNA U | B21: /i2FU/ | C21: U | D21: =LEN(C21) -> 1
A22: 5-Hydroxmethyl dC | B22: /i5HydMe-dC/ | C22: C | D22: =LEN(C22) -> 1
A23: 5-Methyl dC | B23: /i5MedC/ | C23: C | D23: =LEN(C23) -> 1
A24: Int dSpacer | B24: /idSp/ | D24: =LEN(C24) -> 0
A25: Int 6-FAM dT | B25: /i6FAMdT/ | C25: T | D25: =LEN(C25) -> 1
A26: Int AF488 dT | B26: /iAF488dT/ | C26: T | D26: =LEN(C26) -> 1
A27: Int Amino Modifier C6 dT | B27: /iAmMC6T/ | C27: T | D27: =LEN(C27) -> 1
A28: Int BHQ1 dT | B28: /iBHQ1dT/ | C28: T | D28: =LEN(C28) -> 1
A29: Int BHQ2 dT | B29: /iBHQ2dT/ | C29: T | D29: =LEN(C29) -> 1
A30: Int Biotin dT | B30: /iBiodT/ | C30: T | D30: =LEN(C30) -> 1
A31: Int CHCH dT | B31: /iCHCHdT/ | C31: T | D31: =LEN(C31) -> 1
A32: Int Cy3 dT | B32: /iCy3dT/ | C32: T | D32: =LEN(C32) -> 1
A33: Int Cy5 dT | B33: /iCy5dT/ | C33: T | D33: =LEN(C33) -> 1
A34: Int Dabcyl dT | B34: /iDABdT/ | C34: T | D34: =LEN(C34) -> 1
A35: Int Dig dT | B35: /iDigdT/ | C35: T | D35: =LEN(C35) -> 1
A36: Int Ferrocene | B36: /iMFEdT/ | C36: T | D36: =LEN(C36) -> 1
... A43: Int Texas Red dT | B43: /iTexRddT/ | C43: T | D43: =LEN(C43) -> 1
A44: Phosphorothioate | B44: *
A45: Spacer 18 | B45: /iSp18/
A46: Spacer 9 | B46: /iSp9/
...

Sheet 可合成修饰种类
A1: 两端修饰 | C1: 中间修饰 | D1: 代码 | E1: 修饰碱基 | G1: 5'修饰 | H1: 代码 | I1: 3'修饰 | J1: 代码 | K1: 特殊碱基 | L1: 代码
A2: 5'6-FAM,3'BHQ1 | C2: 2`-O-Methyl A | D2: /i2OMeA/ | E2: A | G2: 5'6-FAM | H2: /56-FAM/ | I2: 3'Super Quencher 1 | J2: /3SQ1/ | K2: deoxyInosine (dI) | L2: I
A3: 5'6-FAM,3'BHQ2 | C3: 2`-O-Methyl C | D3: /i2OMeC/ | E3: C | G3: 5'HEX | H3: /5HEX/ | I3: 3'Super Quencher 2 | J3: /3SQ2/ | K3: deoxyUridine (dU) | L3: U
A4: 5'6-FAM,3'Dabcyl | C4: 2`-O-Methyl G | D4: /i2OMeG/ | E4: G | G4: 5'VIC | H4: /5VIC/ | I4: 3'MGB | J4: /3MGB/ | K4: LNA-A | L4: +A
A5: 5'6-FAM,3'Eclipse | C5: 2`-O-Methyl U | D5: /i2OMeU/ | E5: U | G5: 5'BECU_BF650 | H5: /5BF650/ | I5: 3'BHQ0 | J5: /3BHQ0/ | K5: LNA-C | L5: +C
A6: 5'6-FAM,3'MGB | C6: 5-Methyl dC | D6: /i5MedC/ | E6: C | G6: 5'ROX | H6: /5ROX/ | I6: 3'BHQ1 | J6: /3BHQ1/ | K6: LNA-G | L6: +G
A7: 5'6-FAM,3'Super Quencher 1 | C7: Int dSpacer | D7: /idSp/ | G7: 5'CY5 | H7: /5CY5/ | I7: 3'BHQ2 | J7: /3BHQ2/ | K7: LNA-T | L7: +T
A8: 5'6-FAM,3'TAMRA | C8: Int 6-FAM dT | D8: /i6FAMdT/ | E8: T | G8: 5'CY3 | H8: /5CY3/ | I8: 3'BHQ3 | J8: /3BHQ3/ | K8: RNA-A | L8: rA
A9: 5'ATTO425,3'BHQ1 | C9: Int BHQ1 dT | D9: /iBHQ1dT/ | E9: T | G9: 5'Biotin | H9: /5BIO/ | I9: 3'6-FAM | J9: /36-FAM/ | K9: RNA-C | L9: rC
A10: 5'ATTO425,3'MGB | C10: Int BHQ2 dT | D10: /iBHQ2dT/ | E10: T | G10: 5'ATTO425 | H10: /5ATTO425/ | I10: 3'AF488 | J10: /3AF488/ | K10: RNA-G | L10: rG
A11: 5'CY3,3'BHQ2 | C11: Int Cy5 dT | D11: /iCy5dT/ | E11: T | G11: 5'AF488 | H11: /5AF488/ | I11: 3'AMCA | J11: /3AMCA/ | K11: RNA-U | L11: rU
A12: 5'CY3,3'Dabcyl | C12: Int Dabcyl dT | D12: /iDABdT/ | E12: T | G12: 5'AMCA | H12: /5AMCA/ | I12: 3'Aminolinker C6 | J12: /3AmMC6/ | K12: DNA-A | L12: dA
A13: 5'CY3,3'Eclipse | C13: Int HEX dT | D13: /iHEXdT/ | E13: T | G13: 5'Aminolinker C12 | H13: /5AmMC12/ | I13: 3'Aminolinker C7 | J13: /3AmMC7/ | K13: DNA-G | L13: dG
A14: 5'CY3,3'MGB | C14: Int ROX dT | D14: /iROXdT/ | E14: T | G14: 5'Aminolinker C6 | H14: /5AmMC6/ | I14: 3'ATTO425 | J14: /3ATTO425/ | K14: DNA-T | L14: dT
A15: 5'CY3,3'TAMRA | C15: Int TAMRA dT | D15: /iTAMdT/ | E15: T | G15: 5'BHQ1 | H15: /5BHQ1/ | I15: 3'Biotin | J15: /3BIO/ | K15: DNA-C | L15: dC
A16: 5'CY5,3'BHQ2 | C16: Int Texas Red dT | D16: /iTexRddT/ | E16: T | G16: 5'BHQ2 | H16: /5BHQ2/ | I16: 3'CHCH | J16: /3CHCH/
A17: 5'CY5,3'BHQ3 | C17: Phosphorothioate | D17: * | G17: 5'Cholesteryl | H17: /5Chol/ | I17: 3'Cholesteryl | J17: /3Chol/
A18: 5'CY5,3'MGB | C18: Spacer 18 | D18: /iSp18/ | G18: 5'CY5.5 | H18: /5CY5.5/ | I18: 3'CY3 | J18: /3CY3/
A19: 5'CY5.5,3'BHQ2 | C19: Spacer 9 | D19: /iSp9/ | G19: 5'CY7 | H19: /5CY7/ | I19: 3'CY5 | J19: /3CY5/
A20: 5'CY5.5,3'BHQ3 | C20: 2`-O-Methyl B | D20: /i2OMeB/ | E20: B | G20: 5'Dabcyl | H20: /5DAB/ | I20: 3'CY5.5 | J20: /3CY5.5/ | AP20: 0 | AQ20: 0 | AR20: 0 | AS20: 0 | AT20: 0 | AU20: 0 | AV20: 0 | AW20: 0 | AX20: 0 | AY20: 0 | AZ20: 0 | BA20: 0 | BB20: 0 | BC20: 0 | BD20: 0 | BE20: 0 | BF20: 0 | BG20: 0 | BH20: 0 | BI20: 0 | BJ20: 0 | CK20: 0 | CL20: 0 | CM20: 0 | CN20: 0 | CO20: 0 | CP20: 0 | CQ20: 0 | CR20: 0 | CS20: 0 | CT20: 0 | CU20: 0 | CV20: 0 | CW20: 0 | CX20: 0 | CY20: 0 | CZ20: 0 | DA20: 0 | DB20: 0 | DC20: 0 | DD20: 0 | DE20: 0 | DF20: 0 | DG20: 0 | DH20: 0 | DI20: 0 | DJ20: 0 | DK20: 0 | DL20: 0 | DM20: 0
A21: 5'CY7,3'BHQ2 | C21: 2`-O-Methyl D | D21: /i2OMeD/ | E21: D | G21: 5'DIG | H21: /5DIG/ | I21: 3'CY7 | J21: /3CY7/
A22: 5'CY7,3'BHQ3 | C22: 2`-O-Methyl H | D22: /i2OMeH/ | E22: H | G22: 5'Ferrocene | H22: /5Ferrocene/ | I22: 3'Dabcyl | J22: /3DAB/
A23: 5'HEX,3'BHQ1 | C23: 2`-O-Methyl K | D23: /i2OMeK/ | E23: K | G23: 5'FITC | H23: /5FITC/ | I23: 3'ddC | J23: /3ddC/
A24: 5'HEX,3'BHQ2 | C24: 2`-O-Methyl M | D24: /i2OMeM/ | E24: M | G24: 5'JOE | H24: /5JOE/ | I24: 3'Digoxigenin | J24: /3DIG/
A25: 5'HEX,3'Dabcyl | C25: 2`-O-Methyl N | D25: /i2OMeN/ | E25: N | G25: 5'NED | H25: /5NED/ | I25: 3'Eclipse | J25: /3ECL/
A26: 5'HEX,3'Eclipse | C26: 2`-O-Methyl R | D26: /i2OMeR/ | E26: R | G26: 5'Phosphate | H26: /5PHO/ | I26: 3'Ferrocene | J26: /3Ferrocene/
A27: 5'HEX,3'MGB | C27: 2`-O-Methyl S | D27: /i2OMeS/ | E27: S | G27: 5'Quasar 670 | H27: /5Q670/ | I27: 3'FITC | J27: /3FITC/
A28: 5'HEX,3'Super Quencher 1 | C28: 2`-O-Methyl V | D28: /i2OMeV/ | E28: V | G28: 5'Thiol C6 | H28: /5THL/ | I28: 3'HEX | J28: /3HEX/
A29: 5'HEX,3'TAMRA | C29: 2`-O-Methyl W | D29: /i2OMeW/ | E29: W | G29: 5'Spacer 18 | H29: /5SP18/ | I29: 3'Inverted dT | J29: /3InvdT/
A30: 5'JOE,3'BHQ1 | C30: 2`-O-Methyl Y | D30: /i2OMeY/ | E30: Y | G30: 5'Spacer C3 | H30: /5SC3/ | I30: 3'JOE | J30: /3JOE/
A31: 5'JOE,3'Dabcyl | C31: 2F-RNA A | D31: i2FrA | E31: A | G31: 5'TAMRA | H31: /5TAM/ | I31: 3'Phosphate | J31: /3PHO/
A32: 5'JOE,3'Eclipse | C32: 2F-RNA C | D32: i2FrC | E32: C | G32: 5'TET | H32: /5TET/ | I32: 3'Quasar 670 | J32: /3Q670/
... A45: 5'ROX,3'MGB | C45: Int TET dT | D45: /iTETdT/ | E45: T | G45: 5'CAL Fluor Red 635 | H45: /5CAL Fluor Red 635/ | I45: 3'Alkyne | J45: /3Alkyne/
A46: 5'ROX,3'TAMRA | C46: Spacer C12 | D46: /iSpC12/ | G46: 5'DBCO | H46: /5DBCO/
A47: 5'TAMRA,3'BHQ2 | C47: Spacer C3 | D47: /iSpC3/ | G47: 5'Dual Biotin | H47: /5dBIO/
A48: 5'TAMRA,3'Dabcyl | C48: Spacer C6 | D48: /iSp6/ | G48: 5'dual FAM | H48: /5dFAM/
A49: 5'TAMRA,3'Eclipse | C49: deoxyInosine (dI) | D49: I | E49: I | G49: 5'Dylight755 | H49: /5DY755/
A50: 5'TAMRA,3'MGB | C50: deoxyUridine (dU) | D50: U | E50: U | G50: 5'Quasar 705 | H50: /5Q705/
A51: 5'TET,3'BHQ1 | C51: LNA-A | D51: +A | E51: A | G51: 5'rApp | H51: /5rApp/
A52: 5'TET,3'BHQ2 | C52: LNA-C | D52: +C | E52: C | G52: 5'TMT | H52: /5TMT/
...

Sheet 填写说明
A1: 质检代码说明
A2: 检验报告类型 | B2: 代码说明
B3: 不提供质检报告
A4: HPTP | B4: HPLC报告
A5: MSTP | B5: MS报告
A6: H+M | B6: HPLC报告+MS报告
A7: H+F | B7: HPLC报告+全波长扫描报告
A8: M+F | B8: MS报告+全波长扫描报告
A9: H+M+F | B9: HPLC报告+MS报告+全波长扫描报告
A10: H+M+C | B10: HPLC报告+MS报告+溶液交付浓度报告
A11: H+M+F+C | B11: HPLC报告+MS报告+全波长扫描报告+溶液交付浓度报告
A13: 默认参数
A14: 订单类别： | B14: RNA
A15: 交付形式： | B15: 干粉（稳定）
A16: 引物名称 | B16: 引物序列(5'to3') | C16: 反向互补序列(5'to3') | D16: 纯化方式 | E16: 5'修饰 | F16: 3'修饰 | G16: 反向互补5'修饰 | H16: 反向互补3'修饰 | I16: 分装管数 | J16: 每管OD值 | K16: 每管nmoles | L16: 标签类型 | M16: 离心管类型 | N16: 溶解浓度(uM) | O16: 检验报告类型 | P16: 备注 | Q16: 碱基数
B17: ATGCCAGTGCAGTCAGTC | D17: HPLC | I17: 1 | J17: 2 | L17: BLG白色标签 | M17: 1.5ml离心管 | O17: HPTP | Q17: {=LEN(B17)-SUM((LEN(B17)-LEN(SUBSTITUTE(B17,修饰列表!$B$2:$B$79,修饰列表!$D$2:$D$79))))} -> 18
A19: 退火序列填写
A20: 订单类别： | B20: RNA
A21: 交付形式： | B21: 1*TE 100uM
A22: 引物名称 | B22: 引物序列(5'to3') | C22: 反向互补序列(5'to3') | D22: 纯化方式 | E22: 5'修饰 | F22: 3'修饰 | G22: 反向互补5'修饰 | H22: 反向互补3'修饰 | I22: 分装管数 | J22: 每管OD值 | K22: 每管nmoles | L22: 标签类型 | M22: 离心管类型 | N22: 溶解浓度(uM) | O22: 检验报告类型 | P22: 备注 | Q22: 碱基数
B23: ATGCCAGTGCAGTCAGTCAGTC | C23: GACTGACTGACTGCACTGGCAT | D23: HPLC | E23: 5'Aminolinker C6 | G23: 5'Aminolinker C6 | I23: 1 | J23: 2 | L23: BLG白色标签 | M23: 1.5ml离心管 | N23: 100 | O23: HPTP | Q23: {=LEN(B23)-SUM((LEN(B23)-LEN(SUBSTITUTE(B23,修饰列表!$B$2:$B$79,修饰列表!$D$2:$D$79))))} -> 22
A25: RNA中插入DNA序列填写
A26: 订单类别： | B26: RNA
A27: 交付形式： | B27: 干粉（稳定）
A28: 引物名称 | B28: 引物序列(5'to3') | C28: 反向互补序列(5'to3') | D28: 纯化方式 | E28: 5'修饰 | F28: 3'修饰 | G28: 反向互补5'修饰 | H28: 反向互补3'修饰 | I28: 分装管数 | J28: 每管OD值 | K28: 每管nmoles | L28: 标签类型 | M28: 离心管类型 | N28: 溶解浓度(uM) | O28: 检验报告类型 | P28: 备注 | Q28: 碱基数
B29: ATGCCAdGTGCAGdTCAGTCAGTC | D29: HPLC | I29: 1 | J29: 2 | L29: BLG白色标签 | M29: 1.5ml离心管 | O29: HPTP | Q29: {=LEN(B29)-SUM((LEN(B29)-LEN(SUBSTITUTE(B29,修饰列表!$B$2:$B$79,修饰列表!$D$2:$D$79))))} -> 24
