Workbook

Sheet DNA合成订购表
B1: 百力格生物科技（上海）股份有限公司 DNA合成订购表
A4: 订购日期： | F4: 地址：上海市松江区书海路99号23幢
A5: 客户姓名：* | F5: 联系电话：021-67616018, 400-168-8906
A6: 客户单位：* | F6: 网址：www.bioligo.com
A7: 课题组：* | F7: 邮箱：oligo@bioligo.com
A8: 订单类别：* | B8: PCR | F8: 订单要求：
A9: 客户地址：* | F9: 1.此表格仅针对E-mail订单使用，如果工作日19点前2小时未收到回复请及时联系。 2.因为订单是系统自动处理，订单发送前请仔细核对信息, 订单接收2小时后将不能再更改。 3.修饰请用下拉菜单中我们公司的专用代码，如果没有的修饰种类请在备注栏中备注或电话联系我们。 4.特殊碱基和中间修饰填写请参照”填写说明“。 5.交付形式可通过左侧下拉菜单选择，不填写默认为“干粉”；液体交付的订单，收到货后请及时正面朝上存放，防止渗漏。 6.技术支持邮箱：blg-support@bioligo.com。
A10: 客户电话：*
A11: 客户Email：
A12: 交付形式：
A13: 客户ID:
A14: 客户订单号：
A15: 收货人：* | C15: 收货电话：*
A16: 收货地址：* | F16: 兼并碱基代码：A,g＝R；A,C＝M；A,T＝W；C,g=S；C,T＝Y；g,T＝K；A,T,C＝H；g,T,C＝B；g,A,T=D；A,C,g=V；A,C,g,T=N
A17: 发票类型：*
A18: 发票抬头：* | F18: 总OD | G18: =SUMPRODUCT(H20:H10000, I20:I10000) -> 0 | H18: 总nmol | I18: =SUMPRODUCT(H20:H10000, J20:J10000) -> 0
A19: ID* | B19: 客户固定编号 | C19: 引物名称 | D19: 引物序列(5'to3') | E19: 纯化方式 | F19: 5'修饰 | G19: 3'修饰 | H19: 分装管数 | I19: 每管OD值 | J19: 每管nmoles | K19: 标签类型 | L19: 离心管类型 | M19: 溶解浓度（uM) | N19: 检验报告类型 | O19: 备注 | P19: 碱基数 | Q19: 总OD/nmol
P20: =LEN(D20)-SUM((LEN(D20)-LEN(SUBSTITUTE(D20,修饰列表!$B$2:$B$79,修饰列表!$D$2:$D$79)))) -> 0 | Q20: =IF(I20="",H20*J20,H20*I20) -> 0
P21: {=LEN(D21)-SUM((LEN(D21)-LEN(SUBSTITUTE(D21,修饰列表!$B$2:$B$79,修饰列表!$D$2:$D$79))))} -> 0 | Q21: =IF(I21="",H21*J21,H21*I21) -> 0
P22: {=LEN(D4)-SUM((LEN(D4)-LEN(SUBSTITUTE(D4,修饰列表!$B$2:$B$79,修饰列表!$D$2:$D$79))))} -> 0 | Q22: =IF(I22="",H22*J22,H22*I22) -> 0
P23: {=LEN(D23)-SUM((LEN(D23)-LEN(SUBSTITUTE(D23,修饰列表!$B$2:$B$79,修饰列表!$D$2:$D$79))))} -> 0 | Q23: =IF(I23="",H23*J23,H23*I23) -> 0
P24: {=LEN(D24)-SUM((LEN(D24)-LEN(SUBSTITUTE(D24,修饰列表!$B$2:$B$79,修饰列表!$D$2:$D$79))))} -> 0 | Q24: =IF(I24="",H24*J24,H24*I24) -> 0
P25: {=LEN(D25)-SUM((LEN(D25)-LEN(SUBSTITUTE(D25,修饰列表!$B$2:$B$79,修饰列表!$D$2:$D$79))))} -> 0 | Q25: =IF(I25="",H25*J25,H25*I25) -> 0
P26: {=LEN(D26)-SUM((LEN(D26)-LEN(SUBSTITUTE(D26,修饰列表!$B$2:$B$79,修饰列表!$D$2:$D$79))))} -> 0 | Q26: =IF(I26="",H26*J26,H26*I26) -> 0
P27: {=LEN(D27)-SUM((LEN(D27)-LEN(SUBSTITUTE(D27,修饰列表!$B$2:$B$79,修饰列表!$D$2:$D$79))))} -> 0 | Q27: =IF(I27="",H27*J27,H27*I27) -> 0
P28: {=LEN(D28)-SUM((LEN(D28)-LEN(SUBSTITUTE(D28,修饰列表!$B$2:$B$79,修饰列表!$D$2:$D$79))))} -> 0 | Q28: =IF(I28="",H28*J28,H28*I28) -> 0
P29: {=LEN(D29)-SUM((LEN(D29)-LEN(SUBSTITUTE(D29,修饰列表!$B$2:$B$79,修饰列表!$D$2:$D$79))))} -> 0 | Q29: =IF(I29="",H29*J29,H29*I29) -> 0
P30: {=LEN(D30)-SUM((LEN(D30)-LEN(SUBSTITUTE(D30,修饰列表!$B$2:$B$79,修饰列表!$D$2:$D$79))))} -> 0 | Q30: =IF(I30="",H30*J30,H30*I30) -> 0
P31: {=LEN(D31)-SUM((LEN(D31)-LEN(SUBSTITUTE(D31,修饰列表!$B$2:$B$79,修饰列表!$D$2:$D$79))))} -> 0 | Q31: =IF(I31="",H31*J31,H31*I31) -> 0
P32: {=LEN(D32)-SUM((LEN(D32)-LEN(SUBSTITUTE(D32,修饰列表!$B$2:$B$79,修饰列表!$D$2:$D$79))))} -> 0 | Q32: =IF(I32="",H32*J32,H32*I32) -> 0
P33: {=LEN(D33)-SUM((LEN(D33)-LEN(SUBSTITUTE(D33,修饰列表!$B$2:$B$79,修饰列表!$D$2:$D$79))))} -> 0 | Q33: =IF(I33="",H33*J33,H33*I33) -> 0
P34: {=LEN(D34)-SUM((LEN(D34)-LEN(SUBSTITUTE(D34,修饰列表!$B$2:$B$79,修饰列表!$D$2:$D$79))))} -> 0 | Q34: =IF(I34="",H34*J34,H34*I34) -> 0
... P60: {=LEN(D60)-SUM((LEN(D60)-LEN(SUBSTITUTE(D60,修饰列表!$B$2:$B$79,修饰列表!$D$2:$D$79))))} -> 0 | Q60: =IF(I60="",H60*J60,H60*I60) -> 0
P61: =LEN(D61)-SUM((LEN(D61)-LEN(SUBSTITUTE(D61,修饰列表!$B$2:$B$80,修饰列表!$D$2:$D$80)))) -> 0 | Q61: =IF(I61="",H61*J61,H61*I61) -> 0
P62: =LEN(D62)-SUM((LEN(D62)-LEN(SUBSTITUTE(D62,修饰列表!$B$2:$B$80,修饰列表!$D$2:$D$80)))) -> 0 | Q62: =IF(I62="",H62*J62,H62*I62) -> 0
P63: =LEN(D63)-SUM((LEN(D63)-LEN(SUBSTITUTE(D63,修饰列表!$B$2:$B$80,修饰列表!$D$2:$D$80)))) -> 0 | Q63: =IF(I63="",H63*J63,H63*I63) -> 0
P64: =LEN(D64)-SUM((LEN(D64)-LEN(SUBSTITUTE(D64,修饰列表!$B$2:$B$80,修饰列表!$D$2:$D$80)))) -> 0 | Q64: =IF(I64="",H64*J64,H64*I64) -> 0
P65: =LEN(D65)-SUM((LEN(D65)-LEN(SUBSTITUTE(D65,修饰列表!$B$2:$B$80,修饰列表!$D$2:$D$80)))) -> 0 | Q65: =IF(I65="",H65*J65,H65*I65) -> 0
P66: =LEN(D66)-SUM((LEN(D66)-LEN(SUBSTITUTE(D66,修饰列表!$B$2:$B$80,修饰列表!$D$2:$D$80)))) -> 0 | Q66: =IF(I66="",H66*J66,H66*I66) -> 0
P67: =LEN(D67)-SUM((LEN(D67)-LEN(SUBSTITUTE(D67,修饰列表!$B$2:$B$80,修饰列表!$D$2:$D$80)))) -> 0 | Q67: =IF(I67="",H67*J67,H67*I67) -> 0
...

Sheet 修饰列表
B1: DNA修饰 | I1: RNA修饰
A2: 中间修饰 | B2: 代码 | C2: 修饰碱基 | D2: 碱基数 | E2: 常用兼并碱基代码 | H2: 中间修饰 | I2: 代码 | J2: 碱基数 | K2: 常用兼并碱基代码
A3: 2`-O-Methyl A | B3: /i2OMeA/ | C3: A | D3: =LEN(C3) -> 1 | E3: M:(A/C) | F3: V:(A/C/G) | H3: dA | I3: dA | J3: 1 | K3: M:(A/C) | L3: V:(A/C/G)
A4: 2`-O-Methyl B | B4: /i2OMeB/ | C4: B | D4: =LEN(C4) -> 1 | E4: R:(A/G) | F4: H:(A/C/T) | H4: dG | I4: dG | J4: 1 | K4: R:(A/G) | L4: H:(A/C/U)
A5: 2`-O-Methyl C | B5: /i2OMeC/ | C5: C | D5: =LEN(C5) -> 1 | E5: W:(A/T) | F5: D:(A/G/T) | H5: dC | I5: dC | J5: 1 | K5: W:(A/U) | L5: D:(A/G/U)
A6: 2`-O-Methyl D | B6: /i2OMeD/ | C6: D | D6: =LEN(C6) -> 1 | E6: S:(C/G) | F6: B:(C/G/T) | H6: dT | I6: dT | J6: 1 | K6: S:(C/G) | L6: B:(C/G/U)
A7: 2`-O-Methyl G | B7: /i2OMeG/ | C7: G | D7: =LEN(C7) -> 1 | E7: Y:(C/T) | F7: N:(A/G/C/T) | H7: LNA-A | I7: +A | J7: 1 | K7: Y:(C/U) | L7: N:(A/G/C/U)
A8: 2`-O-Methyl H | B8: /i2OMeH/ | C8: H | D8: =LEN(C8) -> 1 | E8: K:(G/T) | H8: LNA-C | I8: +C | J8: 1 | K8: K:(G/U)
A9: 2`-O-Methyl K | B9: /i2OMeK/ | C9: K | D9: =LEN(C9) -> 1 | H9: LNA-G | I9: +G | J9: 1
A10: 2`-O-Methyl M | B10: /i2OMeM/ | C10: M | D10: =LEN(C10) -> 1 | H10: LNA-U | I10: +T | J10: 1
A11: 2`-O-Methyl N | B11: /i2OMeN/ | C11: N | D11: =LEN(C11) -> 1
A12: 2`-O-Methyl R | B12: /i2OMeR/ | C12: R | D12: =LEN(C12) -> 1
A13: 2`-O-Methyl S | B13: /i2OMeS/ | C13: S | D13: =LEN(C13) -> 1
A14: 2`-O-Methyl U | B14: /i2OMeU/ | C14: U | D14: =LEN(C14) -> 1
A15: 2`-O-Methyl V | B15: /i2OMeV/ | C15: V | D15: =LEN(C15) -> 1
A16: 2`-O-Methyl W | B16: /i2OMeW/ | C16: W | D16: =LEN(C16) -> 1
A17: 2`-O-Methyl Y | B17: /i2OMeY/ | C17: Y | D17: =LEN(C17) -> 1
A18: 2F-RNA A | B18: /i2FA/ | C18: A | D18: =LEN(C18) -> 1
A19: 2F-RNA C | B19: /i2FC/ | C19: C | D19: =LEN(C19) -> 1
A20: 2F-RNA G | B20: /i2FG/ | C20: G | D20: =LEN(C20) -> 1
A21: 2F-RNA U | B21: /i2FU/ | C21: U | D21: =LEN(C21) -> 1
A22: 5-Hydroxmethyl dC | B22: /i5HydMe-dC/ | C22: C | D22: =LEN(C22) -> 1
A23: 5-Methyl dC | B23: /i5MedC/ | C23: C | D23: =LEN(C23) -> 1
A24: Int dSpacer | B24: /idSp/ | D24: =LEN(C24) -> 0
A25: Int 6-FAM dT | B25: /i6FAMdT/ | C25: T | D25: =LEN(C25) -> 1
A26: Int AF488 dT | B26: /iAF488dT/ | C26: T | D26: =LEN(C26) -> 1
A27: Int Amino Modifier C6 dT | B27: /iAmMC6T/ | C27: T | D27: =LEN(C27) -> 1
A28: Int BHQ1 dT | B28: /iBHQ1dT/ | C28: T | D28: =LEN(C28) -> 1
A29: Int BHQ2 dT | B29: /iBHQ2dT/ | C29: T | D29: =LEN(C29) -> 1
A30: Int Biotin dT | B30: /iBiodT/ | C30: T | D30: =LEN(C30) -> 1
A31: Int CHCH dT | B31: /iCHCHdT/ | C31: T | D31: =LEN(C31) -> 1
A32: Int Cy3 dT | B32: /iCy3dT/ | C32: T | D32: =LEN(C32) -> 1
A33: Int Cy5 dT | B33: /iCy5dT/ | C33: T | D33: =LEN(C33) -> 1
A34: Int Dabcyl dT | B34: /iDABdT/ | C34: T | D34: =LEN(C34) -> 1
A35: Int Dig dT | B35: /iDigdT/ | C35: T | D35: =LEN(C35) -> 1
A36: Int Ferrocene | B36: /iMFEdT/ | C36: T | D36: =LEN(C36) -> 1
... A43: Int Texas Red dT | B43: /iTexRddT/ | C43: T | D43: =LEN(C43) -> 1
A44: Phosphorothioate | B44: *
A45: Spacer 18 | B45: /iSp18/
A46: Spacer 9 | B46: /iSp9/
...

Sheet 可合成修饰种类
A1: 两端修饰 | C1: 中间修饰 | D1: 代码 | E1: 修饰碱基 | G1: 5'修饰 | H1: 代码 | J1: 3'修饰 | K1: 代码 | M1: 特殊碱基 | N1: 代码
A2: 5'6-FAM,3'BHQ1, | C2: int-2F RNA-A | D2: /i2FrA/ | E2: A | G2: 5' Methylene Blue | H2: /5MBlue/ | J2: 3' Methylene Blue | K2: /3MBlue/ | M2: deoxyInosine (dI) | N2: I
A3: 5'6-FAM,3'DABCYL, | C3: int-2F RNA-C | D3: /i2FrC/ | E3: C | G3: 5'6-FAM | H3: /56-FAM/ | J3: 3'6-FAM | K3: /36-FAM/ | M3: deoxyUridine (dU) | N3: U
A4: 5'6-FAM,3'Eclipse, | C4: int-2F RNA-U | D4: /i2FrU/ | E4: U | G4: 5'Acridinium | H4: /5Acridinium/ | J4: 3'AF488 | K4: /3AF488/ | M4: LNA-A | N4: +A
A5: 5'6-FAM,3'MGB, | C5: int-2F-RNA-G | D5: /i2FrG/ | E5: G | G5: 5'Acrydite | H5: /5Acrydite/ | J5: 3'AF546 | K5: /3AF546/ | M5: LNA-C | N5: +C
A6: 5'6-FAM,3'Super Quencher 1, | C6: int-2'methoxy A | D6: /i2OMeA/ | E6: A | G6: 5'AF350 | H6: /5AF350/ | J6: 3'AF568 | K6: /3AF568/ | M6: LNA-G | N6: +G
A7: 5'6-FAM,3'TAMRA, | C7: int-2'methoxy C | D7: /i2OMeC/ | E7: C | G7: 5'AF430 | H7: /5AF430/ | J7: 3'AF594 | K7: /3AF594/ | M7: LNA-T | N7: +T
A8: 5'AF350,3'BHQ0, | C8: int-2'methoxy G | D8: /i2OMeG/ | E8: G | G8: 5'AF488 | H8: /5AF488/ | J8: 3'AF647 | K8: /3AF647/ | M8: RNA-A | N8: rA
A9: 5'AF350,3'MGB, | C9: int-2'methoxy R | D9: /i2OMeR/ | E9: R | G9: 5'AF532 | H9: /5AF532/ | J9: 3'AF750 | K9: /3AF750/ | M9: RNA-C | N9: rC
A10: 5'AF430,3'BHQ1, | C10: int-2'methoxy U | D10: /i2OMeU/ | E10: U | G10: 5'AF546 | H10: /5AF546/ | J10: 3'Alkyne | K10: /3Alkyne/ | M10: RNA-G | N10: rG
A11: 5'AF647,3'BHQ3, | C11: int-5-Me-iso-dC | D11: /i5MeidC/ | E11: C | G11: 5'AF555 | H11: /5AF555/ | J11: 3'AMCA | K11: /3AMCA/ | M11: RNA-U | N11: rU
A12: 5'AF750,3'BHQ3, | C12: int-5-Methyl dC | D12: /i5MedC/ | E12: C | G12: 5'AF568 | H12: /5AF568/ | J12: 3'Amino Modifier C6 | K12: /3AmMC6/ | M12: DNA-A | N12: dA
... A19: 5'AMCA,3'Super Quencher 1, | C19: int-AF555 dT | D19: /iAF555dT/ | E19: T | G19: 5'Amino Modifier C12 | H19: /5AmMC12/ | J19: 3'BBQ650 | K19: /3BBQ650/ | M19: int-GNA-dT | N19: /iGNAdT/
A20: 5'ATTO 594,3'BHQ2, | C20: int-Alkyne | D20: /iAlkyne/ | G20: 5'Amino Modifier C6 | H20: /5AmMC6/ | J20: 3'BECU_BF650 | K20: /3BF650/ | M20: int-GNA-rU | N20: /iGNArU/
A21: 5'ATTO 647N,3'BHQ2, | C21: int-Amino Modifier C12 | D21: /iAmMC12/ | G21: 5'AS | H21: /5AS/ | J21: 3'BHQ0 | K21: /3BHQ0/ | M21: int-LDNA-A | N21: /iLDNA-A/
A22: 5'ATTO 647N,3'MGB, | C22: int-Amino Modifier C6 dA | D22: /iAmMC6dA/ | E22: A | G22: 5'ATTO 647N | H22: /5ATTO647N/ | J22: 3'BHQ1 | K22: /3BHQ1/ | M22: int-LDNA-C | N22: /iLDNA-C/
A23: 5'ATTO425,3'BHQ0, | C23: int-Amino Modifier C6 dC | D23: /iAmMC6dC/ | E23: C | G23: 5'ATTO390 | H23: /5ATTO390/ | J23: 3'BHQ2 | K23: /3BHQ2/ | M23: int-LDNA-G | N23: /iLDNA-G/
A24: 5'ATTO425,3'BHQ1, | C24: int-Amino Modifier C6 dT | D24: /iAmMC6dT/ | E24: T | G24: 5'ATTO425 | H24: /5ATTO425/ | J24: 3'BHQ3 | K24: /3BHQ3/ | M24: int-LDNA-T | N24: /iLDNA-T/
A25: 5'ATTO425,3'MGB, | C25: int-ATTO425 dT | D25: /i425dT/ | E25: T | G25: 5'ATTO488 | H25: /5ATTO488/ | J25: 3'Biotin | K25: /3BIO/
A26: 5'ATTO425,3'Super Quencher 1, | C26: int-ATTO488 dT | D26: /iATTO488dT/ | E26: T | G26: 5'ATTO495 | H26: /5ATTO495/ | J26: 3'C6-AF546 | K26: /3C6-AF546/
A27: 5'ATTO550,3'BHQ2, | C27: int-ATTO647 dT | D27: /iATTO647dT/ | E27: T | G27: 5'ATTO532 | H27: /5ATTO532/ | J27: 3'C6-DBCO | K27: /3C6-DBCO/
A28: 5'ATTO550,3'Super Quencher-X, | C28: int-Azide dT | D28: /iAzidedT/ | E28: T | G28: 5'ATTO550 | H28: /5ATTO550/ | J28: 3'CHCH | K28: /3CHCH/
A29: 5'BECU_BF650,3'BHQ2, | C29: int-BF535 | D29: /iBF535/ | G29: 5'ATTO565 | H29: /5ATTO565/ | J29: 3'Cholesteryl | K29: /3Chol/
A30: 5'BECU_BF650,3'DABCYL, | C30: int-BF650 dA | D30: /iBF650dA/ | E30: A | G30: 5'ATTO594 | H30: /5ATTO594/ | J30: 3'Cholesteryl-TEG | K30: /3Chol-TEG/
A31: 5'BECU_BF650,3'MGB, | C31: int-BF650 dT | D31: /iBF650dT/ | E31: T | G31: 5'ATTO633 | H31: /5ATTO633/ | J31: 3'CY3 | K31: /3CY3/
A32: 5'BECU_BF650,3'RQP, | C32: int-BHQ1 dT | D32: /iBHQ1dT/ | E32: T | G32: 5'ATTO680 | H32: /5ATTO680/ | J32: 3'CY5 | K32: /3CY5/
A33: 5'BECU_BF650,3'Super Quencher 2, | C33: int-BHQ2 dT | D33: /iBHQ2dT/ | E33: T | G33: 5'Azide | H33: /5Azide/ | J33: 3'CY5.5 | K33: /3CY5.5/
A34: 5'BF490,3'RQ, | C34: int-BIO dT | D34: /iBIOdT/ | E34: T | G34: 5'BECU_BF620 | H34: /5BF620/ | J34: 3'CY7 | K34: /3CY7/
A35: 5'BF490,3'RQA, | C35: int-CY3 dT | D35: /iCY3dT/ | E35: T | G35: 5'BECU_BF650 | H35: /5BF650/ | J35: 3'DABCYL | K35: /3DAB/
A36: 5'BF490,3'RQP, | C36: int-CY5 | D36: /iCY5/ | G36: 5'BECU_BF680 | H36: /5BF680/ | J36: 3'DBCO | K36: /3DBCO/
A37: 5'BF490,3'RQP-MGB, | C37: int-CY5 dT | D37: /iCY5dT/ | E37: T | G37: 5'BF435 | H37: /5BF435/ | J37: 3'ddA | K37: /3ddA/
A38: 5'BF492,3'RQ, | C38: int-CY5.5 dT | D38: /iCY5.5dT/ | E38: T | G38: 5'BF490 | H38: /5BF490/ | J38: 3'ddC | K38: /3ddC/
A39: 5'BF492,3'RQP, | C39: int-Dabcyl dT | D39: /iDABdT/ | E39: T | G39: 5'BF492 | H39: /5BF492/ | J39: 3'ddG | K39: /3ddG/
A40: 5'BF494,3'RQ, | C40: int-DBCO dT | D40: /iDBCOdT/ | E40: T | G40: 5'BF493 | H40: /5BF493/ | J40: 3'ddT | K40: /3ddT/
A41: 5'BF494,3'RQP, | C41: int-DIG dT | D41: /iDIGdT/ | E41: T | G41: 5'BF494 | H41: /5BF494/ | J41: 3'Digoxigenin | K41: /3DIG/
A42: 5'BF533,3'RQ, | C42: int-Dihydroxy | D42: /iDHO/ | G42: 5'BF495 | H42: /5BF495/ | J42: 3'dT | K42: /3dT/
A43: 5'BF533,3'RQA, | C43: int-DMT-BHQ1 | D43: /iBHQ1/ | G43: 5'BF500 | H43: /5BF500/ | J43: 3'Eclipse | K43: /3ECL/
A44: 5'BF533,3'RQP, | C44: int-DMT-BHQ2 | D44: /iBHQ2/ | G44: 5'BF533 | H44: /5BF533/ | J44: 3'Ferrocene | K44: /3MFE/
A45: 5'BF533,3'RQP-MGB, | C45: int-dSpacer | D45: /idsp/ | G45: 5'BF535 | H45: /5BF535/ | J45: 3'FITC | K45: /3FITC/
A46: 5'BF552,3'RQ, | C46: int-Eclipse | D46: /iEclipse/ | G46: 5'BF552 | H46: /5BF552/ | J46: 3'GalNAc | K46: /3GalNAc/
...

Sheet 填写说明
A1: 质检代码说明 | Q1: 溶剂 | R1: 浓度 | S1: 液体交付
A2: 检测报告类型 | B2: 代码说明 | Q2: 1 x TE | R2: 10uM | S2: =$Q$2&R2 -> 1 x TE 10uM
B3: 不提供质检报告 | Q3: 1 x LOW TE | R3: 20uM | S3: =$Q$2&R3 -> 1 x TE 20uM
A4: HPTP | B4: HPLC报告 | Q4: dd H20 | R4: 50uM | S4: =$Q$2&R4 -> 1 x TE 50uM
A5: MSTP | B5: MS报告 | Q5: DEPC水 | R5: 100uM | S5: =$Q$2&R5 -> 1 x TE 100uM
A6: H+M | B6: HPLC报告+MS报告 | R6: 200uM | S6: =$Q$2&R6 -> 1 x TE 200uM
A7: H+F | B7: HPLC报告+全波长扫描报告 | R7: 500uM | S7: =$Q$2&R7 -> 1 x TE 500uM
A8: M+F | B8: MS报告+全波长扫描报告 | S8: =$Q$3&R2 -> 1 x LOW TE 10uM
A9: H+M+F | B9: HPLC报告+MS报告+全波长扫描报告 | S9: =$Q$3&R3 -> 1 x LOW TE 20uM
A10: H+M+C | B10: HPLC报告+MS报告+溶液交付浓度报告 | S10: =$Q$3&R4 -> 1 x LOW TE 50uM
A11: H+M+F+C | B11: HPLC报告+MS报告+全波长扫描报告+溶液交付浓度报告 | S11: =$Q$3&R5 -> 1 x LOW TE 100uM
S12: =$Q$3&R6 -> 1 x LOW TE 200uM
A13: 默认参数 | S13: =$Q$3&R7 -> 1 x LOW TE 500uM
A14: 订单类别：* | S14: =$Q$4&R2 -> dd H20 10uM
A15: 交付格式 | B15: 干粉 | S15: =$Q$4&R3 -> dd H20 20uM
A16: 客户固定编号 | B16: 引物名称 | C16: 引物序列(5'to3') | D16: 纯化方式 | E16: 5'修饰 | F16: 3'修饰 | G16: 分装管数 | H16: 每管的OD值 | I16: 每管nmoles | J16: 标签类型 | K16: 离心管类型 | L16: 溶解浓度（uM) | M16: 检验报告类型 | N16: 备注 | O16: 碱基数 | S16: =$Q$4&R4 -> dd H20 50uM
D17: DSL | J17: BLG透明标签 | K17: 1.5ml离心管 | O17: 0 | S17: =$Q$4&R5 -> dd H20 100uM
D18: UPAGE | J18: BLG透明标签 | K18: 1.5ml离心管 | O18: 0 | S18: =$Q$4&R6 -> dd H20 200uM
D19: PAGE | J19: BLG透明标签 | K19: 1.5ml离心管 | O19: 0 | S19: =$Q$4&R7 -> dd H20 500uM
D20: HPLC | J20: BLG透明标签 | K20: 1.5ml离心管 | M20: H+M | O20: 0 | S20: =$Q$5&R2 -> DEPC水 10uM
S21: =$Q$5&R3 -> DEPC水 20uM
S22: =$Q$5&R4 -> DEPC水 50uM
A23: 常规引物 OD下单填写说明 | S23: =$Q$5&R5 -> DEPC水 100uM
A24: 订单类别：* | B24: PCR | S24: =$Q$5&R6 -> DEPC水 200uM
A25: 交付形式 | B25: 干粉 | S25: =$Q$5&R7 -> DEPC水 500uM
A26: 客户固定编号 | B26: 引物名称 | C26: 引物序列(5'to3') | D26: 纯化方式 | E26: 5'修饰 | F26: 3'修饰 | G26: 分装管数 | H26: 每管的OD值 | I26: 每管nmoles | J26: 标签类型 | K26: 离心管类型 | L26: 溶解浓度（uM) | M26: 检验报告类型 | N26: 备注 | O26: 碱基数
B27: F1 | C27: ATGCATGCATGCATGCATGCATGC | D27: DSL | G27: 5 | H27: 2 | J27: BLG透明标签 | K27: 1.5ml离心管 | O27: 24
B28: F2 | C28: ATGCATGCATGCATGCATGCATGC | D28: UPAGE | G28: 5 | H28: 2 | J28: BLG透明标签 | K28: 1.5ml离心管 | O28: 24
B29: F3 | C29: ATGCATGCATGCATGCATGCATGC | D29: PAGE | G29: 5 | H29: 2 | J29: BLG透明标签 | K29: 1.5ml离心管 | O29: 24
B30: F4 | C30: ATGCATGCATGCATGCATGCATGC | D30: HPLC | G30: 5 | H30: 2 | J30: BLG透明标签 | K30: 1.5ml离心管 | M30: H+M | O30: 24
A33: 常规引物 nmol下单填写说明
A34: 订单类别：* | B34: PCR
A35: 交付形式 | B35: 干粉
A36: 客户固定编号 | B36: 引物名称 | C36: 引物序列(5'to3') | D36: 纯化方式 | E36: 5'修饰 | F36: 3'修饰 | G36: 分装管数 | H36: 每管的OD值 | I36: 每管nmoles | J36: 标签类型 | K36: 离心管类型 | L36: 溶解浓度（uM) | M36: 检验报告类型 | N36: 备注 | O36: 碱基数
B37: P1 | C37: ATGCATGCATGCATGCATGCATGC | D37: PAGE | G37: 1 | I37: 5 | J37: BLG透明标签 | K37: 1.5ml离心管 | M37: MSTP | O37: 24
B38: P2 | C38: ATGCATGCATGCATGCATGCATGC | D38: PAGE | G38: 1 | I38: 5 | J38: BLG透明标签 | K38: 1.5ml离心管 | M38: MSTP | O38: 24
B39: P3 | C39: ATGCATGCATGCATGCATGCATGC | D39: PAGE | G39: 1 | I39: 5 | J39: BLG透明标签 | K39: 1.5ml离心管 | M39: MSTP | O39: 24
B40: P4 | C40: ATGCATGCATGCATGCATGCATGC | D40: PAGE | G40: 1 | I40: 5 | J40: BLG透明标签 | K40: 1.5ml离心管 | M40: MSTP | O40: 24
A43: 修饰填写说明
A44: 订单类别：* | B44: PCR
...
